[2024-05-29T01:12:11.348+0000] {task_context_logger.py:104} ERROR - Executor reports task instance <TaskInstance: recalls_etl_v1.get_raw_data manual__2024-05-29T01:12:10.902518+00:00 [queued]> finished (failed) although the task says it's queued. (Info: None) Was the task killed externally?
