[2024-05-28T17:05:53.904+0000] {local_task_job_runner.py:120} INFO - ::group::Pre task execution logs
[2024-05-28T17:05:53.937+0000] {taskinstance.py:2076} INFO - Dependencies all met for dep_context=non-requeueable deps ti=<TaskInstance: recalls_etl_v1.get_raw_data manual__2024-05-28T17:05:41.632181+00:00 [queued]>
[2024-05-28T17:05:53.949+0000] {taskinstance.py:2076} INFO - Dependencies all met for dep_context=requeueable deps ti=<TaskInstance: recalls_etl_v1.get_raw_data manual__2024-05-28T17:05:41.632181+00:00 [queued]>
[2024-05-28T17:05:53.950+0000] {taskinstance.py:2306} INFO - Starting attempt 1 of 1
[2024-05-28T17:05:53.967+0000] {taskinstance.py:2330} INFO - Executing <Task(PythonOperator): get_raw_data> on 2024-05-28 17:05:41.632181+00:00
[2024-05-28T17:05:53.982+0000] {warnings.py:110} WARNING - /home/***/.local/lib/python3.12/site-packages/***/task/task_runner/standard_task_runner.py:61: DeprecationWarning: This process (pid=663) is multi-threaded, use of fork() may lead to deadlocks in the child.
  pid = os.fork()

[2024-05-28T17:05:53.985+0000] {standard_task_runner.py:63} INFO - Started process 672 to run task
[2024-05-28T17:05:53.986+0000] {standard_task_runner.py:90} INFO - Running: ['***', 'tasks', 'run', 'recalls_etl_v1', 'get_raw_data', 'manual__2024-05-28T17:05:41.632181+00:00', '--job-id', '4', '--raw', '--subdir', 'DAGS_FOLDER/recalls_etl_v1.py', '--cfg-path', '/tmp/tmpnki7q_yt']
[2024-05-28T17:05:53.988+0000] {standard_task_runner.py:91} INFO - Job 4: Subtask get_raw_data
[2024-05-28T17:05:54.071+0000] {task_command.py:426} INFO - Running <TaskInstance: recalls_etl_v1.get_raw_data manual__2024-05-28T17:05:41.632181+00:00 [running]> on host d4d254b5e6e6
[2024-05-28T17:05:54.215+0000] {taskinstance.py:2648} INFO - Exporting env vars: AIRFLOW_CTX_DAG_OWNER='***' AIRFLOW_CTX_DAG_ID='recalls_etl_v1' AIRFLOW_CTX_TASK_ID='get_raw_data' AIRFLOW_CTX_EXECUTION_DATE='2024-05-28T17:05:41.632181+00:00' AIRFLOW_CTX_TRY_NUMBER='1' AIRFLOW_CTX_DAG_RUN_ID='manual__2024-05-28T17:05:41.632181+00:00'
[2024-05-28T17:05:54.217+0000] {taskinstance.py:430} INFO - ::endgroup::
[2024-05-28T17:06:57.751+0000] {logging_mixin.py:188} INFO - <Response [200]>
[2024-05-28T17:06:57.946+0000] {logging_mixin.py:188} INFO - Added 29648 recalled records.
[2024-05-28T17:06:58.352+0000] {taskinstance.py:441} INFO - ::group::Post task execution logs
[2024-05-28T17:06:58.366+0000] {taskinstance.py:2905} ERROR - Task failed with exception
Traceback (most recent call last):
  File "/home/airflow/.local/lib/python3.12/site-packages/airflow/models/taskinstance.py", line 465, in _execute_task
    result = _execute_callable(context=context, **execute_callable_kwargs)
             ^^^^^^^^^^^^^^^^^^^^^^^^^^^^^^^^^^^^^^^^^^^^^^^^^^^^^^^^^^^^^
  File "/home/airflow/.local/lib/python3.12/site-packages/airflow/models/taskinstance.py", line 432, in _execute_callable
    return execute_callable(context=context, **execute_callable_kwargs)
           ^^^^^^^^^^^^^^^^^^^^^^^^^^^^^^^^^^^^^^^^^^^^^^^^^^^^^^^^^^^^
  File "/home/airflow/.local/lib/python3.12/site-packages/airflow/models/baseoperator.py", line 400, in wrapper
    return func(self, *args, **kwargs)
           ^^^^^^^^^^^^^^^^^^^^^^^^^^^
  File "/home/airflow/.local/lib/python3.12/site-packages/airflow/operators/python.py", line 235, in execute
    return_value = self.execute_callable()
                   ^^^^^^^^^^^^^^^^^^^^^^^
  File "/home/airflow/.local/lib/python3.12/site-packages/airflow/operators/python.py", line 252, in execute_callable
    return self.python_callable(*self.op_args, **self.op_kwargs)
           ^^^^^^^^^^^^^^^^^^^^^^^^^^^^^^^^^^^^^^^^^^^^^^^^^^^^^
  File "/opt/airflow/dags/recalls_etl_v1.py", line 63, in get_recall_data
    recall_df.to_csv(raw_output_path, index=False)
  File "/home/airflow/.local/lib/python3.12/site-packages/pandas/core/generic.py", line 3902, in to_csv
    return DataFrameRenderer(formatter).to_csv(
           ^^^^^^^^^^^^^^^^^^^^^^^^^^^^^^^^^^^^
  File "/home/airflow/.local/lib/python3.12/site-packages/pandas/io/formats/format.py", line 1152, in to_csv
    csv_formatter.save()
  File "/home/airflow/.local/lib/python3.12/site-packages/pandas/io/formats/csvs.py", line 247, in save
    with get_handle(
         ^^^^^^^^^^^
  File "/home/airflow/.local/lib/python3.12/site-packages/pandas/io/common.py", line 739, in get_handle
    check_parent_directory(str(handle))
  File "/home/airflow/.local/lib/python3.12/site-packages/pandas/io/common.py", line 604, in check_parent_directory
    raise OSError(rf"Cannot save file into a non-existent directory: '{parent}'")
OSError: Cannot save file into a non-existent directory: '/opt/***/data/raw'
[2024-05-28T17:07:02.923+0000] {taskinstance.py:1206} INFO - Marking task as FAILED. dag_id=recalls_etl_v1, task_id=get_raw_data, run_id=manual__2024-05-28T17:05:41.632181+00:00, execution_date=20240528T170541, start_date=20240528T170553, end_date=20240528T170702
[2024-05-28T17:07:03.007+0000] {standard_task_runner.py:110} ERROR - Failed to execute job 4 for task get_raw_data (Cannot save file into a non-existent directory: '/opt/***/data/raw'; 672)
[2024-05-28T17:07:03.073+0000] {local_task_job_runner.py:240} INFO - Task exited with return code 1
[2024-05-28T17:07:03.430+0000] {taskinstance.py:3498} INFO - 0 downstream tasks scheduled from follow-on schedule check
[2024-05-28T17:07:03.467+0000] {local_task_job_runner.py:222} INFO - ::endgroup::
