[2024-05-28T16:56:08.625+0000] {local_task_job_runner.py:120} INFO - ::group::Pre task execution logs
[2024-05-28T16:56:08.662+0000] {taskinstance.py:2076} INFO - Dependencies all met for dep_context=non-requeueable deps ti=<TaskInstance: recalls_etl_v1.get_raw manual__2024-05-28T16:55:51.241476+00:00 [queued]>
[2024-05-28T16:56:08.677+0000] {taskinstance.py:2076} INFO - Dependencies all met for dep_context=requeueable deps ti=<TaskInstance: recalls_etl_v1.get_raw manual__2024-05-28T16:55:51.241476+00:00 [queued]>
[2024-05-28T16:56:08.678+0000] {taskinstance.py:2306} INFO - Starting attempt 1 of 1
[2024-05-28T16:56:08.692+0000] {taskinstance.py:2330} INFO - Executing <Task(PythonOperator): get_raw> on 2024-05-28 16:55:51.241476+00:00
[2024-05-28T16:56:08.721+0000] {warnings.py:110} WARNING - /home/***/.local/lib/python3.12/site-packages/***/task/task_runner/standard_task_runner.py:61: DeprecationWarning: This process (pid=594) is multi-threaded, use of fork() may lead to deadlocks in the child.
  pid = os.fork()

[2024-05-28T16:56:08.736+0000] {standard_task_runner.py:63} INFO - Started process 596 to run task
[2024-05-28T16:56:08.758+0000] {standard_task_runner.py:90} INFO - Running: ['***', 'tasks', 'run', 'recalls_etl_v1', 'get_raw', 'manual__2024-05-28T16:55:51.241476+00:00', '--job-id', '3', '--raw', '--subdir', 'DAGS_FOLDER/recalls_etl_v1.py', '--cfg-path', '/tmp/tmp9d2ejdsg']
[2024-05-28T16:56:08.760+0000] {standard_task_runner.py:91} INFO - Job 3: Subtask get_raw
[2024-05-28T16:56:09.149+0000] {task_command.py:426} INFO - Running <TaskInstance: recalls_etl_v1.get_raw manual__2024-05-28T16:55:51.241476+00:00 [running]> on host d4d254b5e6e6
[2024-05-28T16:56:09.572+0000] {taskinstance.py:2648} INFO - Exporting env vars: AIRFLOW_CTX_DAG_OWNER='***' AIRFLOW_CTX_DAG_ID='recalls_etl_v1' AIRFLOW_CTX_TASK_ID='get_raw' AIRFLOW_CTX_EXECUTION_DATE='2024-05-28T16:55:51.241476+00:00' AIRFLOW_CTX_TRY_NUMBER='1' AIRFLOW_CTX_DAG_RUN_ID='manual__2024-05-28T16:55:51.241476+00:00'
[2024-05-28T16:56:09.606+0000] {taskinstance.py:430} INFO - ::endgroup::
[2024-05-28T16:56:21.989+0000] {logging_mixin.py:188} INFO - <Response [200]>
[2024-05-28T16:56:22.013+0000] {logging_mixin.py:188} INFO - Added 29648 recalls to list
[2024-05-28T16:56:22.114+0000] {taskinstance.py:441} INFO - ::group::Post task execution logs
[2024-05-28T16:56:22.115+0000] {taskinstance.py:2905} ERROR - Task failed with exception
Traceback (most recent call last):
  File "/home/airflow/.local/lib/python3.12/site-packages/airflow/models/taskinstance.py", line 465, in _execute_task
    result = _execute_callable(context=context, **execute_callable_kwargs)
             ^^^^^^^^^^^^^^^^^^^^^^^^^^^^^^^^^^^^^^^^^^^^^^^^^^^^^^^^^^^^^
  File "/home/airflow/.local/lib/python3.12/site-packages/airflow/models/taskinstance.py", line 432, in _execute_callable
    return execute_callable(context=context, **execute_callable_kwargs)
           ^^^^^^^^^^^^^^^^^^^^^^^^^^^^^^^^^^^^^^^^^^^^^^^^^^^^^^^^^^^^
  File "/home/airflow/.local/lib/python3.12/site-packages/airflow/models/baseoperator.py", line 400, in wrapper
    return func(self, *args, **kwargs)
           ^^^^^^^^^^^^^^^^^^^^^^^^^^^
  File "/home/airflow/.local/lib/python3.12/site-packages/airflow/operators/python.py", line 235, in execute
    return_value = self.execute_callable()
                   ^^^^^^^^^^^^^^^^^^^^^^^
  File "/home/airflow/.local/lib/python3.12/site-packages/airflow/operators/python.py", line 252, in execute_callable
    return self.python_callable(*self.op_args, **self.op_kwargs)
           ^^^^^^^^^^^^^^^^^^^^^^^^^^^^^^^^^^^^^^^^^^^^^^^^^^^^^
  File "/opt/airflow/dags/recalls_etl_v1.py", line 58, in get_recall_data
    recall_df.to_csv(raw_output_path, index=False)
  File "/home/airflow/.local/lib/python3.12/site-packages/pandas/core/generic.py", line 3902, in to_csv
    return DataFrameRenderer(formatter).to_csv(
           ^^^^^^^^^^^^^^^^^^^^^^^^^^^^^^^^^^^^
  File "/home/airflow/.local/lib/python3.12/site-packages/pandas/io/formats/format.py", line 1152, in to_csv
    csv_formatter.save()
  File "/home/airflow/.local/lib/python3.12/site-packages/pandas/io/formats/csvs.py", line 247, in save
    with get_handle(
         ^^^^^^^^^^^
  File "/home/airflow/.local/lib/python3.12/site-packages/pandas/io/common.py", line 739, in get_handle
    check_parent_directory(str(handle))
  File "/home/airflow/.local/lib/python3.12/site-packages/pandas/io/common.py", line 604, in check_parent_directory
    raise OSError(rf"Cannot save file into a non-existent directory: '{parent}'")
OSError: Cannot save file into a non-existent directory: '/opt/***/data/raw'
[2024-05-28T16:56:22.149+0000] {taskinstance.py:1206} INFO - Marking task as FAILED. dag_id=recalls_etl_v1, task_id=get_raw, run_id=manual__2024-05-28T16:55:51.241476+00:00, execution_date=20240528T165551, start_date=20240528T165608, end_date=20240528T165622
[2024-05-28T16:56:22.181+0000] {standard_task_runner.py:110} ERROR - Failed to execute job 3 for task get_raw (Cannot save file into a non-existent directory: '/opt/***/data/raw'; 596)
[2024-05-28T16:56:22.204+0000] {local_task_job_runner.py:240} INFO - Task exited with return code 1
[2024-05-28T16:56:22.244+0000] {taskinstance.py:3498} INFO - 0 downstream tasks scheduled from follow-on schedule check
[2024-05-28T16:56:22.250+0000] {local_task_job_runner.py:222} INFO - ::endgroup::
