[2024-05-29T02:51:46.245+0000] {local_task_job_runner.py:120} INFO - ::group::Pre task execution logs
[2024-05-29T02:51:46.285+0000] {taskinstance.py:2076} INFO - Dependencies all met for dep_context=non-requeueable deps ti=<TaskInstance: recalls_etl_v1.load_data_to_db manual__2024-05-29T02:45:55.871695+00:00 [queued]>
[2024-05-29T02:51:46.299+0000] {taskinstance.py:2076} INFO - Dependencies all met for dep_context=requeueable deps ti=<TaskInstance: recalls_etl_v1.load_data_to_db manual__2024-05-29T02:45:55.871695+00:00 [queued]>
[2024-05-29T02:51:46.299+0000] {taskinstance.py:2306} INFO - Starting attempt 2 of 2
[2024-05-29T02:51:47.079+0000] {taskinstance.py:2330} INFO - Executing <Task(PythonOperator): load_data_to_db> on 2024-05-29 02:45:55.871695+00:00
[2024-05-29T02:51:47.091+0000] {warnings.py:110} WARNING - /home/***/.local/lib/python3.12/site-packages/***/task/task_runner/standard_task_runner.py:61: DeprecationWarning: This process (pid=193) is multi-threaded, use of fork() may lead to deadlocks in the child.
  pid = os.fork()

[2024-05-29T02:51:47.094+0000] {standard_task_runner.py:63} INFO - Started process 195 to run task
[2024-05-29T02:51:47.092+0000] {standard_task_runner.py:90} INFO - Running: ['***', 'tasks', 'run', 'recalls_etl_v1', 'load_data_to_db', 'manual__2024-05-29T02:45:55.871695+00:00', '--job-id', '10', '--raw', '--subdir', 'DAGS_FOLDER/recalls_etl_v1.py', '--cfg-path', '/tmp/tmp2f1w4pvb']
[2024-05-29T02:51:47.095+0000] {standard_task_runner.py:91} INFO - Job 10: Subtask load_data_to_db
[2024-05-29T02:51:47.165+0000] {task_command.py:426} INFO - Running <TaskInstance: recalls_etl_v1.load_data_to_db manual__2024-05-29T02:45:55.871695+00:00 [running]> on host fdca39f1bf3a
[2024-05-29T02:51:47.261+0000] {taskinstance.py:2648} INFO - Exporting env vars: AIRFLOW_CTX_DAG_OWNER='***' AIRFLOW_CTX_DAG_ID='recalls_etl_v1' AIRFLOW_CTX_TASK_ID='load_data_to_db' AIRFLOW_CTX_EXECUTION_DATE='2024-05-29T02:45:55.871695+00:00' AIRFLOW_CTX_TRY_NUMBER='2' AIRFLOW_CTX_DAG_RUN_ID='manual__2024-05-29T02:45:55.871695+00:00'
[2024-05-29T02:51:47.262+0000] {taskinstance.py:430} INFO - ::endgroup::
[2024-05-29T02:51:48.405+0000] {logging_mixin.py:188} INFO - Success: Loaded 29648 recall records to recalls_db.
[2024-05-29T02:51:48.407+0000] {python.py:237} INFO - Done. Returned value was: None
[2024-05-29T02:51:48.408+0000] {taskinstance.py:441} INFO - ::group::Post task execution logs
[2024-05-29T02:51:48.417+0000] {taskinstance.py:1206} INFO - Marking task as SUCCESS. dag_id=recalls_etl_v1, task_id=load_data_to_db, run_id=manual__2024-05-29T02:45:55.871695+00:00, execution_date=20240529T024555, start_date=20240529T025146, end_date=20240529T025148
[2024-05-29T02:51:48.476+0000] {local_task_job_runner.py:240} INFO - Task exited with return code 0
[2024-05-29T02:51:48.494+0000] {taskinstance.py:3498} INFO - 0 downstream tasks scheduled from follow-on schedule check
[2024-05-29T02:51:48.497+0000] {local_task_job_runner.py:222} INFO - ::endgroup::
