[2024-05-29T02:46:42.543+0000] {local_task_job_runner.py:120} INFO - ::group::Pre task execution logs
[2024-05-29T02:46:42.570+0000] {taskinstance.py:2076} INFO - Dependencies all met for dep_context=non-requeueable deps ti=<TaskInstance: recalls_etl_v1.load_data_to_db manual__2024-05-29T02:45:55.871695+00:00 [queued]>
[2024-05-29T02:46:42.581+0000] {taskinstance.py:2076} INFO - Dependencies all met for dep_context=requeueable deps ti=<TaskInstance: recalls_etl_v1.load_data_to_db manual__2024-05-29T02:45:55.871695+00:00 [queued]>
[2024-05-29T02:46:42.582+0000] {taskinstance.py:2306} INFO - Starting attempt 1 of 2
[2024-05-29T02:46:42.794+0000] {taskinstance.py:2330} INFO - Executing <Task(PythonOperator): load_data_to_db> on 2024-05-29 02:45:55.871695+00:00
[2024-05-29T02:46:42.804+0000] {warnings.py:110} WARNING - /home/***/.local/lib/python3.12/site-packages/***/task/task_runner/standard_task_runner.py:61: DeprecationWarning: This process (pid=155) is multi-threaded, use of fork() may lead to deadlocks in the child.
  pid = os.fork()

[2024-05-29T02:46:42.806+0000] {standard_task_runner.py:63} INFO - Started process 157 to run task
[2024-05-29T02:46:42.806+0000] {standard_task_runner.py:90} INFO - Running: ['***', 'tasks', 'run', 'recalls_etl_v1', 'load_data_to_db', 'manual__2024-05-29T02:45:55.871695+00:00', '--job-id', '9', '--raw', '--subdir', 'DAGS_FOLDER/recalls_etl_v1.py', '--cfg-path', '/tmp/tmp1ba934vn']
[2024-05-29T02:46:42.809+0000] {standard_task_runner.py:91} INFO - Job 9: Subtask load_data_to_db
[2024-05-29T02:46:42.888+0000] {task_command.py:426} INFO - Running <TaskInstance: recalls_etl_v1.load_data_to_db manual__2024-05-29T02:45:55.871695+00:00 [running]> on host fdca39f1bf3a
[2024-05-29T02:46:42.983+0000] {taskinstance.py:2648} INFO - Exporting env vars: AIRFLOW_CTX_DAG_OWNER='***' AIRFLOW_CTX_DAG_ID='recalls_etl_v1' AIRFLOW_CTX_TASK_ID='load_data_to_db' AIRFLOW_CTX_EXECUTION_DATE='2024-05-29T02:45:55.871695+00:00' AIRFLOW_CTX_TRY_NUMBER='1' AIRFLOW_CTX_DAG_RUN_ID='manual__2024-05-29T02:45:55.871695+00:00'
[2024-05-29T02:46:42.984+0000] {taskinstance.py:430} INFO - ::endgroup::
[2024-05-29T02:46:43.162+0000] {taskinstance.py:441} INFO - ::group::Post task execution logs
[2024-05-29T02:46:43.163+0000] {taskinstance.py:2905} ERROR - Task failed with exception
Traceback (most recent call last):
  File "/home/airflow/.local/lib/python3.12/site-packages/sqlalchemy/engine/base.py", line 1910, in _execute_context
    self.dialect.do_execute(
  File "/home/airflow/.local/lib/python3.12/site-packages/sqlalchemy/engine/default.py", line 736, in do_execute
    cursor.execute(statement, parameters)
psycopg2.errors.InvalidSchemaName: schema "data" does not exist
LINE 2: CREATE TABLE data.recalls (
                     ^


The above exception was the direct cause of the following exception:

Traceback (most recent call last):
  File "/home/airflow/.local/lib/python3.12/site-packages/airflow/models/taskinstance.py", line 465, in _execute_task
    result = _execute_callable(context=context, **execute_callable_kwargs)
             ^^^^^^^^^^^^^^^^^^^^^^^^^^^^^^^^^^^^^^^^^^^^^^^^^^^^^^^^^^^^^
  File "/home/airflow/.local/lib/python3.12/site-packages/airflow/models/taskinstance.py", line 432, in _execute_callable
    return execute_callable(context=context, **execute_callable_kwargs)
           ^^^^^^^^^^^^^^^^^^^^^^^^^^^^^^^^^^^^^^^^^^^^^^^^^^^^^^^^^^^^
  File "/home/airflow/.local/lib/python3.12/site-packages/airflow/models/baseoperator.py", line 400, in wrapper
    return func(self, *args, **kwargs)
           ^^^^^^^^^^^^^^^^^^^^^^^^^^^
  File "/home/airflow/.local/lib/python3.12/site-packages/airflow/operators/python.py", line 235, in execute
    return_value = self.execute_callable()
                   ^^^^^^^^^^^^^^^^^^^^^^^
  File "/home/airflow/.local/lib/python3.12/site-packages/airflow/operators/python.py", line 252, in execute_callable
    return self.python_callable(*self.op_args, **self.op_kwargs)
           ^^^^^^^^^^^^^^^^^^^^^^^^^^^^^^^^^^^^^^^^^^^^^^^^^^^^^
  File "/opt/airflow/dags/recalls_etl_v1.py", line 92, in load_to_db
    df.to_sql('recalls', con=engine, schema='data', if_exists='replace', index=False)
  File "/home/airflow/.local/lib/python3.12/site-packages/pandas/util/_decorators.py", line 333, in wrapper
    return func(*args, **kwargs)
           ^^^^^^^^^^^^^^^^^^^^^
  File "/home/airflow/.local/lib/python3.12/site-packages/pandas/core/generic.py", line 3008, in to_sql
    return sql.to_sql(
           ^^^^^^^^^^^
  File "/home/airflow/.local/lib/python3.12/site-packages/pandas/io/sql.py", line 788, in to_sql
    return pandas_sql.to_sql(
           ^^^^^^^^^^^^^^^^^^
  File "/home/airflow/.local/lib/python3.12/site-packages/pandas/io/sql.py", line 1948, in to_sql
    table = self.prep_table(
            ^^^^^^^^^^^^^^^^
  File "/home/airflow/.local/lib/python3.12/site-packages/pandas/io/sql.py", line 1852, in prep_table
    table.create()
  File "/home/airflow/.local/lib/python3.12/site-packages/pandas/io/sql.py", line 936, in create
    self._execute_create()
  File "/home/airflow/.local/lib/python3.12/site-packages/pandas/io/sql.py", line 922, in _execute_create
    self.table.create(bind=self.pd_sql.con)
  File "/home/airflow/.local/lib/python3.12/site-packages/sqlalchemy/sql/schema.py", line 962, in create
    bind._run_ddl_visitor(ddl.SchemaGenerator, self, checkfirst=checkfirst)
  File "/home/airflow/.local/lib/python3.12/site-packages/sqlalchemy/engine/base.py", line 2221, in _run_ddl_visitor
    visitorcallable(self.dialect, self, **kwargs).traverse_single(element)
  File "/home/airflow/.local/lib/python3.12/site-packages/sqlalchemy/sql/visitors.py", line 524, in traverse_single
    return meth(obj, **kw)
           ^^^^^^^^^^^^^^^
  File "/home/airflow/.local/lib/python3.12/site-packages/sqlalchemy/sql/ddl.py", line 899, in visit_table
    self.connection.execute(
  File "/home/airflow/.local/lib/python3.12/site-packages/sqlalchemy/engine/base.py", line 1385, in execute
    return meth(self, multiparams, params, _EMPTY_EXECUTION_OPTS)
           ^^^^^^^^^^^^^^^^^^^^^^^^^^^^^^^^^^^^^^^^^^^^^^^^^^^^^^
  File "/home/airflow/.local/lib/python3.12/site-packages/sqlalchemy/sql/ddl.py", line 80, in _execute_on_connection
    return connection._execute_ddl(
           ^^^^^^^^^^^^^^^^^^^^^^^^
  File "/home/airflow/.local/lib/python3.12/site-packages/sqlalchemy/engine/base.py", line 1477, in _execute_ddl
    ret = self._execute_context(
          ^^^^^^^^^^^^^^^^^^^^^^
  File "/home/airflow/.local/lib/python3.12/site-packages/sqlalchemy/engine/base.py", line 1953, in _execute_context
    self._handle_dbapi_exception(
  File "/home/airflow/.local/lib/python3.12/site-packages/sqlalchemy/engine/base.py", line 2134, in _handle_dbapi_exception
    util.raise_(
  File "/home/airflow/.local/lib/python3.12/site-packages/sqlalchemy/util/compat.py", line 211, in raise_
    raise exception
  File "/home/airflow/.local/lib/python3.12/site-packages/sqlalchemy/engine/base.py", line 1910, in _execute_context
    self.dialect.do_execute(
  File "/home/airflow/.local/lib/python3.12/site-packages/sqlalchemy/engine/default.py", line 736, in do_execute
    cursor.execute(statement, parameters)
sqlalchemy.exc.ProgrammingError: (psycopg2.errors.InvalidSchemaName) schema "data" does not exist
LINE 2: CREATE TABLE data.recalls (
                     ^

[SQL: 
CREATE TABLE data.recalls (
	recall_id BIGINT, 
	organization TEXT, 
	product_name TEXT, 
	issue TEXT, 
	category TEXT, 
	updated_at TEXT, 
	data_received_at TEXT, 
	issue_category TEXT, 
	data_ingested_at TIMESTAMP WITHOUT TIME ZONE
)

]
(Background on this error at: https://sqlalche.me/e/14/f405)
[2024-05-29T02:46:43.197+0000] {taskinstance.py:1206} INFO - Marking task as UP_FOR_RETRY. dag_id=recalls_etl_v1, task_id=load_data_to_db, run_id=manual__2024-05-29T02:45:55.871695+00:00, execution_date=20240529T024555, start_date=20240529T024642, end_date=20240529T024643
[2024-05-29T02:46:43.217+0000] {standard_task_runner.py:110} ERROR - Failed to execute job 9 for task load_data_to_db ((psycopg2.errors.InvalidSchemaName) schema "data" does not exist
LINE 2: CREATE TABLE data.recalls (
                     ^

[SQL: 
CREATE TABLE data.recalls (
	recall_id BIGINT, 
	organization TEXT, 
	product_name TEXT, 
	issue TEXT, 
	category TEXT, 
	updated_at TEXT, 
	data_received_at TEXT, 
	issue_category TEXT, 
	data_ingested_at TIMESTAMP WITHOUT TIME ZONE
)

]
(Background on this error at: https://sqlalche.me/e/14/f405); 157)
[2024-05-29T02:46:43.262+0000] {local_task_job_runner.py:240} INFO - Task exited with return code 1
[2024-05-29T02:46:43.279+0000] {taskinstance.py:3498} INFO - 0 downstream tasks scheduled from follow-on schedule check
[2024-05-29T02:46:43.282+0000] {local_task_job_runner.py:222} INFO - ::endgroup::
